Workbook
Name SelectedTrack: Dashboard!$B$7

Sheet Start Here
A1: RCWS Doctoral Degree Planner
A2: An adaptable, accessible planning and progress-tracking workbook for rhetoric and composition doctoral students, based on the appendix to "Navigating Uncertain Terrain."
A5: How to Use This Workbook
A7: 1. Start on the Dashboard tab: fill in your name and program details, and choose your career track from the dropdown. Your track selection drives the highlighting on the Degree Planner.
A8: 2. Do your planning on the Degree Planner tab: it lists every requirement and suggested milestone from the guide. Edit "Target Year" for any item to fit your own pace — a traditional 5-year plan or an extended timeline of up to 8 or more years. Update "Status" as you make progress.
A9: 3. Focus on your track: rows tagged "All Tracks" apply to everyone. Rows tagged with a specific career track are dimmed in the "Relevant to Selected Track?" column when they don't match your Dashboard selection — use the column's filter arrow and choose "Show" to see only what applies to you.
A10: 4. Watch your progress: the Dashboard updates automatically with totals and percentages overall, by year, by category, and for your selected track, as soon as you change a Status on the Degree Planner.
A11: 5. Fill-in cells are shaded pale gold throughout the workbook — these are places for you to add your own institution's deadlines, names, and details. Everything else can be edited too; nothing is locked.
A12: 6. Three tabs are just for you: Paper Trail & Patterns, the Identity & Values Check-In, and the Mentoring Expectations Agreement on Committee & Mentors. None of them are counted toward degree progress.
A16: Status Legend
A17: ○ Not Started
A18: ◐ In Progress
... A26: What's in Each Tab
A27: Tab | B27: What it's for
A28: Dashboard | B28: Your info, career-track selector, and live progress summary.
A29: Glossary | B29: Field-specific acronyms and terms (WPA, WAC, IDP, Prospectus, etc.).
A30: Field Resources | B30: Directory of RCWS-field organizations, journals, conferences, publishers/book series, and listservs, with links.
A31: Degree Planner | B31: The master flexible checklist — requirements and suggestions, with editable Target Year, Status, and Actual Completion Date so you can see your pace over time.
A32: Career Tracks Reference | B32: Full detail behind each of the six career tracks, for comparing paths before you choose.
A33: Committee & Mentors | B33: Guidance for selecting a committee, a fillable list of your mentors by role, and an optional Mentoring Expectations Agreement template.
A34: Semester Planner | B34: A term-by-term course-planning grid for Years 1-8.
A35: Individual Dev Plan | B35: A yearly goal-setting template across degree, skills, career, personal, and funding goals.
A36: Identity & Values Check-In | B36: Optional, once-a-year reflection on disciplinary identity, teaching persona, professional identity, and personal/spiritual growth — separate from tracked progress.
A37: Job Market Dossier | B37: What goes in an academic job application packet, with length/audience notes.
A38: Paper Trail & Patterns | B38: Optional logs: a documentation record for accommodation/funding decisions, and a private space to notice recurring patterns.

Sheet Glossary
A1: Glossary and Key Terms
A3: Acronym / Term | B3: Definition
A4: RCWS | B4: Rhetoric, Composition, and Writing Studies
A5: WPA | B5: Writing Program Administrator
A6: WC | B6: Writing Center
A7: WAC | B7: Writing Across the Curriculum
A8: CCCC | B8: Conference on College Composition and Communication (major national conference in the field) (now de-charted 2026)
A9: RSA | B9: Rhetoric Society of America (major national conference in the field)
A10: RA | B10: Research Assistant
A11: TA | B11: Teaching Assistant
A12: IDP | B12: Individual Development Plan
A13: Portfolio | B13: A curated set of teaching artifacts and reflective statements used for assessment or exams
A14: Prospectus | B14: A 3–10+ page document describing dissertation questions, methods, and significance; read by your committee
... A20: Burnout | B20: Exhaustion — physical, emotional, or both — that builds from sustained overwork without adequate recovery. Frequently normalized in academic culture as just part of the job; it isn't, and the conditions that produce it are structural (workload, funding, job-market pressure), not a matter of individual discipline.

Sheet Field Resources
A1: Field Resources: Organizations, Journals, Conferences & Publishers
A2: A directory of RCWS-field organizations, journals, conferences, publishers/book series, and listservs, compiled from sense-making resource-sharing documents created after the de-chartering of CCCC. Links were current as of compilation — fields and web addresses change, so verify before relying on one. A blank Link cell means no reliable public link was available; search the name directly instead.
A4: Professional Organizations
A5: Field and field-adjacent organizations; many run their own conferences and journals noted below.
A6: Name | B6: Notes | C6: Link
A7: Association for Business Communication (ABC) | C7: https://www.businesscommunication.org/home
A8: Association of Computing Machinery Special Interest Group on Design of Communication (ACM SIGDOC) | C8: https://sigdoc.acm.org/
A9: Association for Writing Across the Curriculum (AWAC) | B9: Affiliated w/ IWAC and WAC Clearinghouse | C9: https://wacassociation.org/iwac-conference/
A10: Association of Teachers of Technical Writing (ATTW) | C10: https://attw.org/
A11: Coalition for Community Writing (CCW) | B11: Affiliated with Reflections and Community Literacy Journal, and the biennial Conference on Community Writing | C11: https://communitywriting.org/
A12: Coalition of Feminist Scholars in the History of Rhetoric and Composition (CFSHRC) | B12: Affiliated w/ Peitho and the biennial FemRhet Conference | C12: https://cfshrc.org/
A13: Community Literacies Collaboratory | C13: https://communityliteraciescollaboratory.com
A14: Consortium on Graduate Communication (CGC) | C14: https://gradconsortium.org/
A15: Council of Writing Program Administrators (CWPA) | C15: https://www.wpacouncil.org/aws/CWPA/pt/sp/home_page
A16: Council on Basic Writing (CBW) | B16: Affiliated w/ Journal of Basic Writing | C16: https://cbwblog.wordpress.com/about/
A17: Council on Programs in Technical and Scientific Communication (CPTSC) | C17: https://cptsc.org/
A18: Critical Language Awareness Collective (CLAC) | C18: https://clacollective.org/
A19: European Association for Teachers of Academic Writing (EATAW) | B19: Affiliated w/ Journal of Academic Writing | C19: https://www.eataw.eu/
A20: Global Society of Online Literacy Educators (GSOLE) | C20: https://gsole.org/
A21: International Society for the Advancement of Writing Research (ISAWR) | B21: Affiliated w/ WRAB conference | C21: https://www.isawr.org/
A22: International Writing Centers Association (IWCA) | C22: https://writingcenters.org/
A23: IEEE ProComm / Professional Communication Society | B23: Yearly conference in July; TPC professionals and educators | C23: https://procomm.ieee.org/
A24: Jesuit Rhetoric and Composition Network (JCRN) | B24: Affiliated with the Association of Jesuit Colleges and Universities; meets at RSA | C24: https://ajcunet.edu/networks/jesuit-rhetoric-composition-network/
A25: Rhetoric Society of America (RSA) | C25: https://rhetoricsociety.org/
A26: Rhetoricians of Health and Medicine (RHM) | B26: Publishes the RHM Journal | C26: https://medicalrhetoric.com/
A27: Small Liberal Arts Colleges – Writing Program Administrators (SLAC-WPA) | C27: https://slacwpa.org/
A28: Symposium for Second Language Writing (SSLW) | B28: Affiliated w/ Journal of Second Language Writing | C28: https://pmatsuda.net/sslw/
A29: Two-Year College English Association (TYCA) | B29: Affiliated with TETYC and NCTE; regional TYCAs are not | C29: https://ncte.org/groups/tyca/tyca-about-us/
A30: Writing Analytics (SIG) | C30: —
A31: Latin American Writing Studies Association | C31: https://www.estudiosdelaescritura.org/home-english.html
A32: Kenneth Burke Society (KBS) | C32: https://kbjournal.org/kbs
A33: Writing through the Lifespan Collaboration | C33: http://lifespanwriting.org
A34: Writing for Research and Academic Practice (WRAP) | C34: https://wrapnetwork.org/
A35: AAAL — American Association for Applied Linguistics | C35: —
A36: AACU — Association of American Colleges and Universities | C36: —
A37: ARSTM — Association for the Rhetoric of Science, Technology, and Medicine | C37: —
A38: ASHR — American Society for the History of Rhetoric | C38: —
A39: CRRAR — Center for Research on Reasoning, Argumentation, & Rhetoric | C39: —
A40: EARLI (SIG – Writing) — European Association for Research on Learning and Instruction | C40: —
A41: ELATE — English Language Arts Teacher Educators | C41: —
...

Sheet Dashboard
A1: My Degree Planning Dashboard
A2: Fill in your details, choose your career track, and watch your progress update automatically as you mark items complete on the Degree Planner tab.
A4: Student Name:
A5: Program / Institution:
A6: Program Start Year:
A7: My Career Track:
A9: Overall Progress
A11: Total Items | B11: Not Started | C11: In Progress | D11: Complete | E11: % Complete
A12: =COUNTIF('Degree Planner'!$D$5:$D$77,"<>") -> 72 | B12: =COUNTIFS('Degree Planner'!$D$5:$D$77,"<>",'Degree Planner'!$G$5:$G$77,"○ Not Started") -> 72 | C12: =COUNTIFS('Degree Planner'!$D$5:$D$77,"<>",'Degree Planner'!$G$5:$G$77,"◐ In Progress") -> 0 | D12: =COUNTIFS('Degree Planner'!$D$5:$D$77,"<>",'Degree Planner'!$G$5:$G$77,"✓ Complete") -> 0 | E12: =IFERROR(D12/A12,0) -> 0
A14: Progress on My Selected Track
A16: Selected Track | B16: Total Relevant Items | C16: Complete | D16: % Complete
A17: =IF(SelectedTrack="","(none selected)",SelectedTrack) -> (none selected) | B17: =COUNTIFS('Degree Planner'!$M$5:$M$77,"Show",'Degree Planner'!$D$5:$D$77,"<>") -> 47 | C17: =COUNTIFS('Degree Planner'!$M$5:$M$77,"Show",'Degree Planner'!$G$5:$G$77,"✓ Complete") -> 0 | D17: =IFERROR(C17/B17,0) -> 0
A19: Progress by Year
A21: Year | B21: Goal | C21: Complete | D21: % Complete
A22: Year 1 | B22: =COUNTIFS('Degree Planner'!$A$5:$A$77,A22,'Degree Planner'!$D$5:$D$77,"<>") -> 11 | C22: =COUNTIFS('Degree Planner'!$A$5:$A$77,A22,'Degree Planner'!$G$5:$G$77,"✓ Complete") -> 0 | D22: =IFERROR(C22/B22,0) -> 0
A23: Year 2 | B23: =COUNTIFS('Degree Planner'!$A$5:$A$77,A23,'Degree Planner'!$D$5:$D$77,"<>") -> 13 | C23: =COUNTIFS('Degree Planner'!$A$5:$A$77,A23,'Degree Planner'!$G$5:$G$77,"✓ Complete") -> 0 | D23: =IFERROR(C23/B23,0) -> 0
A24: Year 3 | B24: =COUNTIFS('Degree Planner'!$A$5:$A$77,A24,'Degree Planner'!$D$5:$D$77,"<>") -> 13 | C24: =COUNTIFS('Degree Planner'!$A$5:$A$77,A24,'Degree Planner'!$G$5:$G$77,"✓ Complete") -> 0 | D24: =IFERROR(C24/B24,0) -> 0
A25: Year 4 | B25: =COUNTIFS('Degree Planner'!$A$5:$A$77,A25,'Degree Planner'!$D$5:$D$77,"<>") -> 15 | C25: =COUNTIFS('Degree Planner'!$A$5:$A$77,A25,'Degree Planner'!$G$5:$G$77,"✓ Complete") -> 0 | D25: =IFERROR(C25/B25,0) -> 0
A26: Year 5 | B26: =COUNTIFS('Degree Planner'!$A$5:$A$77,A26,'Degree Planner'!$D$5:$D$77,"<>") -> 20 | C26: =COUNTIFS('Degree Planner'!$A$5:$A$77,A26,'Degree Planner'!$G$5:$G$77,"✓ Complete") -> 0 | D26: =IFERROR(C26/B26,0) -> 0
A27: Year 6 | B27: =COUNTIFS('Degree Planner'!$A$5:$A$77,A27,'Degree Planner'!$D$5:$D$77,"<>") -> 0 | C27: =COUNTIFS('Degree Planner'!$A$5:$A$77,A27,'Degree Planner'!$G$5:$G$77,"✓ Complete") -> 0 | D27: =IFERROR(C27/B27,0) -> 0
A28: Year 7 | B28: =COUNTIFS('Degree Planner'!$A$5:$A$77,A28,'Degree Planner'!$D$5:$D$77,"<>") -> 0 | C28: =COUNTIFS('Degree Planner'!$A$5:$A$77,A28,'Degree Planner'!$G$5:$G$77,"✓ Complete") -> 0 | D28: =IFERROR(C28/B28,0) -> 0
A29: Year 8+ | B29: =COUNTIFS('Degree Planner'!$A$5:$A$77,A29,'Degree Planner'!$D$5:$D$77,"<>") -> 0 | C29: =COUNTIFS('Degree Planner'!$A$5:$A$77,A29,'Degree Planner'!$G$5:$G$77,"✓ Complete") -> 0 | D29: =IFERROR(C29/B29,0) -> 0
A31: Progress by Category
A33: Category | B33: Actual | C33: Complete | D33: % Complete
A34: Coursework | B34: =COUNTIFS('Degree Planner'!$C$5:$C$77,A34,'Degree Planner'!$D$5:$D$77,"<>") -> 2 | C34: =COUNTIFS('Degree Planner'!$C$5:$C$77,A34,'Degree Planner'!$G$5:$G$77,"✓ Complete") -> 0 | D34: =IFERROR(C34/B34,0) -> 0
A35: Conference & Professional Development | B35: =COUNTIFS('Degree Planner'!$C$5:$C$77,A35,'Degree Planner'!$D$5:$D$77,"<>") -> 11 | C35: =COUNTIFS('Degree Planner'!$C$5:$C$77,A35,'Degree Planner'!$G$5:$G$77,"✓ Complete") -> 0 | D35: =IFERROR(C35/B35,0) -> 0
A36: Teaching Development | B36: =COUNTIFS('Degree Planner'!$C$5:$C$77,A36,'Degree Planner'!$D$5:$D$77,"<>") -> 9 | C36: =COUNTIFS('Degree Planner'!$C$5:$C$77,A36,'Degree Planner'!$G$5:$G$77,"✓ Complete") -> 0 | D36: =IFERROR(C36/B36,0) -> 0
A37: Exams & Portfolio | B37: =COUNTIFS('Degree Planner'!$C$5:$C$77,A37,'Degree Planner'!$D$5:$D$77,"<>") -> 2 | C37: =COUNTIFS('Degree Planner'!$C$5:$C$77,A37,'Degree Planner'!$G$5:$G$77,"✓ Complete") -> 0 | D37: =IFERROR(C37/B37,0) -> 0
A38: Publication & Research | B38: =COUNTIFS('Degree Planner'!$C$5:$C$77,A38,'Degree Planner'!$D$5:$D$77,"<>") -> 6 | C38: =COUNTIFS('Degree Planner'!$C$5:$C$77,A38,'Degree Planner'!$G$5:$G$77,"✓ Complete") -> 0 | D38: =IFERROR(C38/B38,0) -> 0
A39: Service | B39: =COUNTIFS('Degree Planner'!$C$5:$C$77,A39,'Degree Planner'!$D$5:$D$77,"<>") -> 10 | C39: =COUNTIFS('Degree Planner'!$C$5:$C$77,A39,'Degree Planner'!$G$5:$G$77,"✓ Complete") -> 0 | D39: =IFERROR(C39/B39,0) -> 0
A40: Prospectus | B40: =COUNTIFS('Degree Planner'!$C$5:$C$77,A40,'Degree Planner'!$D$5:$D$77,"<>") -> 1 | C40: =COUNTIFS('Degree Planner'!$C$5:$C$77,A40,'Degree Planner'!$G$5:$G$77,"✓ Complete") -> 0 | D40: =IFERROR(C40/B40,0) -> 0
A41: Dissertation | B41: =COUNTIFS('Degree Planner'!$C$5:$C$77,A41,'Degree Planner'!$D$5:$D$77,"<>") -> 2 | C41: =COUNTIFS('Degree Planner'!$C$5:$C$77,A41,'Degree Planner'!$G$5:$G$77,"✓ Complete") -> 0 | D41: =IFERROR(C41/B41,0) -> 0
A42: Job Market | B42: =COUNTIFS('Degree Planner'!$C$5:$C$77,A42,'Degree Planner'!$D$5:$D$77,"<>") -> 13 | C42: =COUNTIFS('Degree Planner'!$C$5:$C$77,A42,'Degree Planner'!$G$5:$G$77,"✓ Complete") -> 0 | D42: =IFERROR(C42/B42,0) -> 0
A43: Funding | B43: =COUNTIFS('Degree Planner'!$C$5:$C$77,A43,'Degree Planner'!$D$5:$D$77,"<>") -> 1 | C43: =COUNTIFS('Degree Planner'!$C$5:$C$77,A43,'Degree Planner'!$G$5:$G$77,"✓ Complete") -> 0 | D43: =IFERROR(C43/B43,0) -> 0

Sheet Degree Planner
A1: Degree Planner — Flexible Year-by-Year Checklist
A2: Set your own pace: edit Target Year for any item to build a traditional 5-year plan or an extended timeline of up to 8+ years. Update Status as you go, and log your Actual Completion Date to see your own pace over time — not a normative one. Pale gold cells are for your own details. See the "Relevant to Selected Track" column to focus on your chosen career track (set on the Dashboard).
A4: Target Year | B4: Timing / Semester Notes | C4: Category | D4: Requirement / Task | E4: Priority | F4: Career Track | G4: Status | H4: Evidence / Deliverable & Reviewer | I4: Institution-Specific Deadline (fill in) | J4: Access Planning / Notes (fill in) | K4: Actual Completion Date (fill in) | L4: Pace / Gap Notes (fill in) | M4: Relevant to Selected Track?
A5: Year 1 | B5: Flexible / Ongoing | C5: Coursework | D5: Complete first-year coursework | E5: Required | F5: All Tracks | G5: ○ Not Started | M5: =IF(OR($F5="All Tracks",$F5=SelectedTrack),"Show","Hide") -> Show
A6: Year 1 | B6: Flexible / Ongoing | C6: Institutional Paperwork | D6: Register for required credit load (e.g., 18 credits) | E6: Required | F6: All Tracks | G6: ○ Not Started | M6: =IF(OR($F6="All Tracks",$F6=SelectedTrack),"Show","Hide") -> Show
A7: Year 1 | B7: Flexible / Ongoing | C7: Conference & Professional Development | D7: Attend a pre-conference workshop | E7: Suggested | F7: All Tracks | G7: ○ Not Started | M7: =IF(OR($F7="All Tracks",$F7=SelectedTrack),"Show","Hide") -> Show
A8: Year 1 | B8: Flexible / Ongoing | C8: Conference & Professional Development | D8: Join a professional society | E8: Suggested | F8: All Tracks | G8: ○ Not Started | M8: =IF(OR($F8="All Tracks",$F8=SelectedTrack),"Show","Hide") -> Show
A9: Year 1 | B9: Ongoing, Years 1-5 | C9: Teaching Development | D9: Demonstrate teaching readiness (syllabus, teaching philosophy, observation) | E9: Required | F9: All Tracks | G9: ○ Not Started | H9: Course syllabus; teaching philosophy; observation | Reviewer: Teaching mentor | J9: Online contingency accommodation for high pain days | M9: =IF(OR($F9="All Tracks",$F9=SelectedTrack),"Show","Hide") -> Show
A10: Year 1 | B10: Flexible / Ongoing | C10: Conference & Professional Development | D10: Attend industry-adjacent workshops (UX writing, content strategy, information design) | E10: Suggested | F10: Industry | G10: ○ Not Started | M10: =IF(OR($F10="All Tracks",$F10=SelectedTrack),"Show","Hide") -> Hide
A11: Year 1 | B11: Flexible / Ongoing | C11: Conference & Professional Development | D11: Join a professional organization outside academia | E11: Suggested | F11: Industry | G11: ○ Not Started | M11: =IF(OR($F11="All Tracks",$F11=SelectedTrack),"Show","Hide") -> Hide
A12: Year 1 | B12: Flexible / Ongoing | C12: Sustaining Practices & Care | D12: Ask your advisor or a faculty mentor directly how they manage work/life balance and boundaries | E12: Suggested | F12: All Tracks | G12: ○ Not Started | M12: =IF(OR($F12="All Tracks",$F12=SelectedTrack),"Show","Hide") -> Show
A13: Year 1 | B13: Flexible / Ongoing | C13: Sustaining Practices & Care | D13: Run a one-week time-tracking self-study to see where your hours actually go | E13: Suggested | F13: All Tracks | G13: ○ Not Started | M13: =IF(OR($F13="All Tracks",$F13=SelectedTrack),"Show","Hide") -> Show
A14: Year 1 | B14: Flexible / Ongoing | C14: Sustaining Practices & Care | D14: Identify a sustainable self-care routine and treat it as part of your professional development, not an afterthought | E14: Suggested | F14: All Tracks | G14: ○ Not Started | M14: =IF(OR($F14="All Tracks",$F14=SelectedTrack),"Show","Hide") -> Show
A15: Year 1 | B15: Flexible / Ongoing | C15: Sustaining Practices & Care | D15: Build or join a care collective or mutual-aid network with peers (shared resources, errands, community) | E15: Suggested | F15: All Tracks | G15: ○ Not Started | M15: =IF(OR($F15="All Tracks",$F15=SelectedTrack),"Show","Hide") -> Show
A16: Year 1 | E16: Required | F16: All Tracks | G16: ○ Not Started | M16: =IF(OR($F16="All Tracks",$F16=SelectedTrack),"Show","Hide") -> Show
A17: Year 2 | B17: Flexible / Ongoing | C17: Coursework | D17: Complete coursework requirements | E17: Required | F17: All Tracks | G17: ○ Not Started | M17: =IF(OR($F17="All Tracks",$F17=SelectedTrack),"Show","Hide") -> Show
A18: Year 2 | B18: Flexible / Ongoing | C18: Institutional Paperwork | D18: Register for required credit load (e.g., 18 credits) | E18: Required | F18: All Tracks | G18: ○ Not Started | M18: =IF(OR($F18="All Tracks",$F18=SelectedTrack),"Show","Hide") -> Show
A19: Year 2 | B19: Flexible / Ongoing | C19: Exams & Portfolio | D19: Begin preparing for portfolio / comprehensive exams | E19: Required | F19: All Tracks | G19: ○ Not Started | M19: =IF(OR($F19="All Tracks",$F19=SelectedTrack),"Show","Hide") -> Show
A20: Year 2 | B20: Flexible / Ongoing | C20: Publication & Research | D20: Begin drafting a manuscript for publication | E20: Suggested | F20: All Tracks | G20: ○ Not Started | M20: =IF(OR($F20="All Tracks",$F20=SelectedTrack),"Show","Hide") -> Show
A21: Year 2 | B21: Flexible / Ongoing | C21: Conference & Professional Development | D21: Attend a regional conference | E21: Suggested | F21: All Tracks | G21: ○ Not Started | M21: =IF(OR($F21="All Tracks",$F21=SelectedTrack),"Show","Hide") -> Show
A22: Year 2 | B22: Flexible / Ongoing | C22: Service | D22: Take on departmental service | E22: Suggested | F22: All Tracks | G22: ○ Not Started | M22: =IF(OR($F22="All Tracks",$F22=SelectedTrack),"Show","Hide") -> Show
A23: Year 2 | B23: Flexible / Ongoing | C23: Service | D23: Take on an administrative / WPA role | E23: Suggested | F23: Teaching Track & WPA | G23: ○ Not Started | M23: =IF(OR($F23="All Tracks",$F23=SelectedTrack),"Show","Hide") -> Hide
A24: Year 2 | B24: Flexible / Ongoing | C24: Conference & Professional Development | D24: Complete an internship | E24: Suggested | F24: Technical & Professional Communication | G24: ○ Not Started | M24: =IF(OR($F24="All Tracks",$F24=SelectedTrack),"Show","Hide") -> Hide
A25: Year 2 | B25: Flexible / Ongoing | C25: Publication & Research | D25: Begin building an industry-facing portfolio | E25: Suggested | F25: Industry | G25: ○ Not Started | M25: =IF(OR($F25="All Tracks",$F25=SelectedTrack),"Show","Hide") -> Hide
A26: Year 2 | B26: Flexible / Ongoing | C26: Conference & Professional Development | D26: Conduct informational interviews with alumni working outside academia | E26: Suggested | F26: Industry | G26: ○ Not Started | M26: =IF(OR($F26="All Tracks",$F26=SelectedTrack),"Show","Hide") -> Hide
A27: Year 2 | B27: Flexible / Ongoing | C27: Sustaining Practices & Care | D27: Join or start a peer writing group centered on community and support, not just output | E27: Suggested | F27: All Tracks | G27: ○ Not Started | M27: =IF(OR($F27="All Tracks",$F27=SelectedTrack),"Show","Hide") -> Show
A28: Year 2 | B28: Flexible / Ongoing | C28: Sustaining Practices & Care | D28: Find or create a faculty-free space for peer connection | E28: Suggested | F28: All Tracks | G28: ○ Not Started | M28: =IF(OR($F28="All Tracks",$F28=SelectedTrack),"Show","Hide") -> Show
A29: Year 2 | B29: Flexible / Ongoing | C29: Sustaining Practices & Care | D29: Set a recurring check-in (solo or with peers) to name academic guilt, imposter syndrome, or burnout when they show up | E29: Suggested | F29: All Tracks | G29: ○ Not Started | M29: =IF(OR($F29="All Tracks",$F29=SelectedTrack),"Show","Hide") -> Show
A30: Year 3 | B30: End of Year 2 or Year 3 | C30: Exams & Portfolio | D30: Complete portfolio / comprehensive exams | E30: Required | F30: All Tracks | G30: ○ Not Started | H30: Portfolio artifacts; exam results | Reviewer: Committee | J30: 1.5x extension of comprehensive exams | M30: =IF(OR($F30="All Tracks",$F30=SelectedTrack),"Show","Hide") -> Show
A31: Year 3 | B31: Flexible / Ongoing | C31: Institutional Paperwork | D31: Submit comprehensive exam paperwork | E31: Required | F31: All Tracks | G31: ○ Not Started | M31: =IF(OR($F31="All Tracks",$F31=SelectedTrack),"Show","Hide") -> Show
A32: Year 3 | B32: 6-12 months post-comps | C32: Prospectus | D32: Prepare and defend dissertation prospectus | E32: Required | F32: All Tracks | G32: ○ Not Started | H32: Prospectus document; IRB approval if needed | Reviewer: Committee | J32: Defense questions provided in advance | M32: =IF(OR($F32="All Tracks",$F32=SelectedTrack),"Show","Hide") -> Show
A33: Year 3 | B33: Flexible / Ongoing | C33: Publication & Research | D33: Submit first publication | E33: Suggested | F33: All Tracks | G33: ○ Not Started | M33: =IF(OR($F33="All Tracks",$F33=SelectedTrack),"Show","Hide") -> Show
A34: Year 3 | B34: Flexible / Ongoing | C34: Service | D34: Take on an administrative role (WPA / Writing Center / WAC) | E34: Suggested | F34: All Tracks | G34: ○ Not Started | M34: =IF(OR($F34="All Tracks",$F34=SelectedTrack),"Show","Hide") -> Show
A35: Year 3 | B35: Flexible / Ongoing | C35: Teaching Development | D35: Develop an upper-level course | E35: Required | F35: Teaching Track & WPA | G35: ○ Not Started | M35: =IF(OR($F35="All Tracks",$F35=SelectedTrack),"Show","Hide") -> Hide
A36: Year 3 | B36: Flexible / Ongoing | C36: Teaching Development | D36: Develop an upper-level course | E36: Suggested | F36: Writing Center Track | G36: ○ Not Started | M36: =IF(OR($F36="All Tracks",$F36=SelectedTrack),"Show","Hide") -> Hide
A37: Year 3 | B37: Flexible / Ongoing | C37: Service | D37: Engage in community partnership work | E37: Required | F37: Community-Engaged Public Rhetorics | G37: ○ Not Started | M37: =IF(OR($F37="All Tracks",$F37=SelectedTrack),"Show","Hide") -> Hide
A38: Year 3 | B38: Flexible / Ongoing | C38: Teaching Development | D38: Develop a service-learning course | E38: Suggested | F38: Community-Engaged Public Rhetorics | G38: ○ Not Started | M38: =IF(OR($F38="All Tracks",$F38=SelectedTrack),"Show","Hide") -> Hide
A39: Year 3 | B39: Flexible / Ongoing | C39: Service | D39: Take on an administrative or research role | E39: Suggested | F39: Technical & Professional Communication | G39: ○ Not Started | M39: =IF(OR($F39="All Tracks",$F39=SelectedTrack),"Show","Hide") -> Hide
A40: Year 3 | B40: Flexible / Ongoing | C40: Conference & Professional Development | D40: Complete an internship or practicum in an industry role | E40: Suggested | F40: Industry | G40: ○ Not Started | M40: =IF(OR($F40="All Tracks",$F40=SelectedTrack),"Show","Hide") -> Hide
A41: Year 3 | B41: Flexible / Ongoing | C41: Conference & Professional Development | D41: Attend an industry (not academic) conference | E41: Suggested | F41: Industry | G41: ○ Not Started | M41: =IF(OR($F41="All Tracks",$F41=SelectedTrack),"Show","Hide") -> Hide
...

Sheet Career Tracks Reference
A1: Career Track Summaries and Yearly Plans
A2: Full detail behind each track's suggestions on the Degree Planner. Pick your track on the Dashboard, then use this sheet to see the whole picture for that path.
A4: Tenure Track R&C
A5: For students aiming for a tenure-track research position; emphasizes publications, conference presence, and an upper-level course.
A6: Year | B6: Required | C6: Suggested
A7: Year 1 | B7: Coursework | C7: Pre-conference workshop
A8: Year 2 | B8: Coursework complete | C8: Begin manuscript; Regional conference; Dept service
A9: Year 3 | B9: Portfolio/comps | C9: Submit publication; Admin role
A10: Year 4 | B10: Dissertation writing | C10: Draft second publication; Teach upper-level course
A11: Year 5 | B11: Defend; Job market dossier | C11: Submit revised/second publication; National service
A13: Teaching Track & WPA
A14: For students prioritizing teaching careers or administrative roles (WPA); emphasizes diverse teaching prep and program administration experience.
A15: Year | B15: Required | C15: Suggested
A16: Year 1 | B16: Coursework | C16: Pre-conference workshop
A17: Year 2 | B17: Coursework complete | C17: Begin manuscript; Regional conference; Admin role
A18: Year 3 | B18: Portfolio/comps; Develop upper-level course | C18: Submit publication; Dept service
A19: Year 4 | B19: Dissertation work | C19: Admin role; Teach upper-level course
A20: Year 5 | B20: Defend; Job market dossier | C20: National service
A22: Writing Center Track
A23: For students focused on writing center research and administration; emphasizes writing center leadership and assessment.
A24: Year | B24: Required | C24: Suggested
A25: Year 1 | B25: Coursework | C25: Pre-conference workshop
A26: Year 2 | B26: Coursework complete | C26: Begin manuscript; Regional conference
A27: Year 3 | B27: Portfolio/comps | C27: Submit publication; Develop upper-level course
A28: Year 4 | B28: Dissertation work | C28: Writing center admin role; conduct assessment
A29: Year 5 | B29: Defend | C29: Teach upper-level course; National service
A31: Community-Engaged Public Rhetorics
A32: For students working with community partners and service-learning; emphasizes sustained partnerships and community projects.
A33: Year | B33: Required | C33: Suggested
A34: Year 1 | B34: Coursework | C34: Pre-conference workshop
A35: Year 2 | B35: Coursework complete | C35: Begin manuscript; Regional conference
A36: Year 3 | B36: Portfolio/comps; Community engagement | C36: Submit publication; Develop service-learning course
A37: Year 4 | B37: Dissertation work | C37: Community partnership activities
A38: Year 5 | B38: Defend | C38: National service; Continued engagement
A40: Technical & Professional Communication
A41: For students focused on technical communication in industry or academia; emphasizes technical writing courses and applied projects.
A42: Year | B42: Required | C42: Suggested
A43: Year 1 | B43: Coursework | C43: Pre-conference workshop
A44: Year 2 | B44: Coursework complete | C44: Begin manuscript; Internship
A45: Year 3 | B45: Portfolio/comps | C45: Submit publication; Admin/research role
...

Sheet Committee & Mentors
A1: Committee Guidance and Mentors
A2: Guidance for choosing a committee, plus tools for making mentoring relationships explicit — vague mentoring is one of the most commonly named failure points for disabled graduate students.
A4: Committee selection summary: Aim for a committee with (1) subject expertise, (2) methodological expertise, (3) intellectual alignment, and (4) an external reader when appropriate.
A5: Important note: If you don't mesh with the faculty member at your university who is supposed to be an expert in your subject matter, don't work with them. Identify another faculty member willing to support your research and find other ways to develop your knowledge of the research subject through other mentoring relationships.
A6: Before you commit: mentoring styles vary a lot, and mismatches are far easier to navigate in year one than in year three. Where you can, ask a prospective advisor or committee member directly about their mentoring style and how they handle their own work/life balance and boundaries — their answer (or reluctance to answer) tells you a lot before you're committed to working with them.
A8: Mentor Role | B8: Who fills this role for you (fill in)
A9: General mentor
A10: Teaching mentor
A11: Expert-specific mentor
A12: Peer mentor
A15: Mentoring Expectations Agreement (optional template)
A17: A short, low-stakes way to make an unspoken mentoring relationship explicit — for your own clarity, or as an actual conversation with a mentor. Fill in one row per mentoring relationship you want to formalize.
A18: Mentor Name | B18: Role | C18: Meeting Frequency | D18: What my mentor commits to | E18: What I commit to | F18: If either of us needs to step back / renegotiate
B19: General mentor
B20: Teaching mentor
B21: Expert-specific mentor
B22: Peer mentor

Sheet Semester Planner
A1: Semester by Semester Planner
A2: Years 1-5. Add rows for Years 6-8 if you are on an extended timeline.
A4: Term | B4: Course 1 | C4: Course 2 | D4: Course 3 | E4: Other responsibilities
A5: Fall Y1 | B5: [Type here] | C5: [Type here] | D5: [Type here] | E5: [Type here]
A6: Spring Y1 | B6: [Type here] | C6: [Type here] | D6: [Type here] | E6: [Type here]
A7: Fall Y2 | B7: [Type here] | C7: [Type here] | D7: [Type here] | E7: [Type here]
A8: Spring Y2 | B8: [Type here] | C8: [Type here] | D8: [Type here] | E8: [Type here]
A9: Fall Y3 | B9: [Students in their 3rd year and beyond typically need to register for very specific courses and credits-please determine your institutional context] | C9: n/a | D9: n/a | E9: Exams; Prospectus prep
A10: Spring Y3 | B10: [Type here] | C10: n/a | D10: n/a | E10: Prospectus defense; Begin dissertation
A11: Fall Y4 | B11: [Type here] | C11: n/a | D11: n/a | E11: Dissertation writing; Conferences
A12: Spring Y4 | B12: [Type here] | C12: n/a | D12: n/a | E12: Dissertation writing
A13: Fall Y5 | B13: [Type here] | C13: n/a | D13: n/a | E13: Job market prep; Dossier finalization
A14: Spring Y5 | B14: [Type here] | C14: n/a | D14: n/a | E14: Dissertation defense; Graduation steps
A15: Fall Y6
A16: Spring Y6
A17: Fall Y7
A18: Spring Y7
A19: Fall Y8
A20: Spring Y8

Sheet Individual Dev Plan
A1: Individual Development Plan Template
A2: Rows are filled in with examples of possible goals; replace with your specifics.
A4: Year | B4: Degree goals | C4: Skills goals | D4: Career goals | E4: Personal goals | F4: Funding goals | G4: Access Planning
A5: Year 1 | B5: Coursework progress | C5: Design syllabus | D5: Join professional society | E5: Wellness habit | F5: TA/RA funding | G5: Online contingency accommodation for high pain days
A6: Year 2 | B6: Coursework complete | C6: Assessment design | D6: Present at conference | E6: Build social network | F6: Conference funding | G6: Online contingency accommodation for high pain days
A7: Year 3 | B7: Comps passed | C7: Grant writing | D7: Publish first article | E7: Sleep routine | F7: Fellowship applications | G7: 1.5x extension on comprehensive exams. Defense questions in advance
A8: Year 4 | B8: Prospectus approved | C8: Fellowship applications | D8: Prepare job materials | E8: Daily walk | F8: Dissertation fellowship | G8: Writing groups
A9: Year 5 | B9: Dissertation defense | C9: Job talk practice | D9: Apply for positions | E9: Reflect on career | F9: Finalize funding | G9: Requesting accommodations during campus visits

Sheet Identity & Values Check-In
A1: Identity & Values Check-In
A2: The Degree Planner tracks what you complete. This tab is for who you're becoming while you do it. Reflect once-a-year across four areas of development.
A4: Year | B4: Disciplinary Identity | C4: Teaching Persona | D4: Professional Identity | E4: Personal & Spiritual Growth
B5: What does it mean to think, write, and argue like a scholar in your field this year? What ideas, methods, or conversations are you starting to claim as your own? | C5: Who are you becoming as a teacher this year? What kind of classroom are you building, and what from your own experience as a student are you carrying into it — or deliberately leaving behind? | D5: How do you want to be known in your field? What are you building toward, and what are you not willing to compromise to get there? | E5: What's sustaining you outside of your scholarly work this year? What does growth, rest, or groundedness look like for you right now?
A6: Year 1
A7: Year 2
A8: Year 3
A9: Year 4
A10: Year 5
A11: Year 6
A12: Year 7
A13: Year 8+

Sheet Job Market Dossier
A1: Job Market Dossier Guide
A2: A curated packet of materials used when applying for academic jobs. Track completion of each item on the Degree Planner (Category = Job Market); use this sheet for length/audience detail.
A4: Dossier Item | B4: Audience / Length Notes | C4: Status
A5: Cover letter(s) | C5: ○ Not Started
A6: CV | C6: ○ Not Started
A7: Teaching philosophy | B7: 1 page | C7: ○ Not Started
A8: Research statement | B8: 2 pages | C8: ○ Not Started
A9: Diversity statement | B9: (if relevant) | C9: ○ Not Started
A10: Administrative statement | B10: (if relevant) | C10: ○ Not Started
A11: Dissertation abstract | C11: ○ Not Started
A12: Teaching portfolio | C12: ○ Not Started
A13: Writing sample(s) | C13: ○ Not Started
A14: Transcripts | C14: ○ Not Started
A15: Reference letters | C15: ○ Not Started

Sheet Paper Trail & Patterns
A1: Paper Trail & Patterns
A2: Record any documentation filed or points of friction noted as you navigate your degree.
A4: Documentation Log
A5: Keep a short record of anything related to accommodations, funding, or institutional decisions.
A6: Date | B6: Category | C6: Who (person / office) | D6: What was said or approved | E6: Where it's documented | F6: Follow-up needed?
A23: Patterns & Notes
A25: A place to notice recurring friction points over time — not a formal complaint, just a record for yourself. Naming a pattern is often the first step toward addressing it, whether that stays private or becomes something you choose to raise with your program later.
A26: Date | B26: What happened | C26: Pattern you're noticing | D26: Notes

Sheet Lists
A1: CareerTrackChoices | B1: CareerTrackAll | C1: YearChoices | D1: CategoryChoices | E1: PriorityChoices | F1: StatusChoices | G1: RelationshipChoices | H1: DisclosedChoices | I1: PaperTrailCatChoices | J1: YesNoChoices
A2: Tenure Track R&C | B2: All Tracks | C2: Year 1 | D2: Coursework | E2: Required | F2: ○ Not Started | G2: Advisor | H2: Yes - Formal accommodation | I2: Accommodation | J2: Yes
A3: Teaching Track & WPA | B3: Tenure Track R&C | C3: Year 2 | D3: Institutional Paperwork | E3: Suggested | F3: ◐ In Progress | G3: Committee Member | H3: Yes - Informal only | I3: Funding | J3: No
A4: Writing Center Track | B4: Teaching Track & WPA | C4: Year 3 | D4: Conference & Professional Development | F4: ✓ Complete | G4: Cohort Peer | H4: Partial | I4: Academic / Program
A5: Community-Engaged Public Rhetorics | B5: Writing Center Track | C5: Year 4 | D5: Teaching Development | G5: Department Admin/Staff | H5: No | I5: Other
A6: Technical & Professional Communication | B6: Community-Engaged Public Rhetorics | C6: Year 5 | D6: Exams & Portfolio | G6: Mentor | H6: Prefer not to say
A7: Industry | B7: Technical & Professional Communication | C7: Year 6 | D7: Publication & Research | G7: Other
B8: Industry | C8: Year 7 | D8: Service
C9: Year 8+ | D9: Prospectus
D10: Dissertation
D11: Job Market
D12: Funding
D13: Sustaining Practices & Care
